Workbook

Sheet main
A1: election_number | B1: logical_order | C1: election_year | D1: party | E1: elected_president | F1: president_number | G1: popular_vote | H1: popular_vote_percent | I1: electoral_votes | J1: t1 | K1: t2 | L1: t3 | M1: t4 | N1: t5 | O1: t6 | P1: pvt | Q1: misc | R1: link | S1: desc | T1: popular_vote_percent_vat | U1: election_number_text | V1: won_the_election | W1: candidates | X1: candidates_won | Y1: candidates_lost | Z1: election_link | AA1: comment
A2: 1 | B2: =VLOOKUP(D2,party!A:E,5,0) -> 1 | C2: 1788 | D2: Independent | E2: George Washington | G2: 43782 | H2: 1 | I2: 69 | P2: 100.0% * | Q2: =IF(IFERROR(VLOOKUP($D2,party!$A:$D,2,0),"")="","",IFERROR(VLOOKUP($D2,party!$A:$D,2,0),"")) -> Not a party. | R2: =IF(IFERROR(VLOOKUP($D2,party!$A:$D,3,0),"")="","",IFERROR(VLOOKUP($D2,party!$A:$D,3,0),"")) -> https://en.wikipedia.org/wiki/Independent_politician | S2: =IF(IFERROR(VLOOKUP($D2,party!$A:$D,4,0),"")="","",IFERROR(VLOOKUP($D2,party!$A:$D,4,0),"")) -> An independent, non-partisan politician or non-affiliated politician is a politician not affiliated with any political party or bureaucratic association. There are numerous reasons why someone may stand for office as an independent. George Washington is the only U.S. president elected as an independent to date. Washington opposed the development of political parties. He feared that partisanship would eventually destroy the country, and famously warned against "the baneful effects of the spirit of party" in his 1796 Farewell Address. | T2: =IF(H2="", "", VALUE(H2)) -> 1 | U2: =_xlfn.CONCAT(TEXT(A2,"#"), IF(AND(A2>=10, A2<=19), "th", IF(MOD(A2,10) = 1, "st", IF(MOD(A2,10) = 2, "nd", IF(MOD(A2,10) = 3, "rd", "th"))))) -> 1st | V2: TRUE | X2: =IF(V2, W2, "") | Y2: =IF(NOT(V2), W2, "") | Z2: https://en.wikipedia.org/wiki/1788%E2%80%9389_United_States_presidential_election | AA2: * States had varying methods for choosing presidential electors. In five states, the state legislature chose electors. The other six chose electors through some form involving a popular vote, though in only two states did the choice depend directly on a statewide vote.
A3: 1 | B3: =VLOOKUP(D3,party!A:E,5,0) -> 10 | C3: 1788 | D3: Federalist | G3: 0 | I3: 65 | P3: n/a * | Q3: =IF(IFERROR(VLOOKUP($D3,party!$A:$D,2,0),"")="","",IFERROR(VLOOKUP($D3,party!$A:$D,2,0),"")) | R3: =IF(IFERROR(VLOOKUP($D3,party!$A:$D,3,0),"")="","",IFERROR(VLOOKUP($D3,party!$A:$D,3,0),"")) -> https://en.wikipedia.org/wiki/Federalist_Party | S3: =IF(IFERROR(VLOOKUP($D3,party!$A:$D,4,0),"")="","",IFERROR(VLOOKUP($D3,party!$A:$D,4,0),"")) -> The Federalist Party was a conservative and nationalist American political party and the first political party in the United States. It dominated the national government under Alexander Hamilton from 1789 to 1801. The party was defeated by the Democratic-Republican Party in 1800, and it became a minority party while keeping its stronghold in New England. It made a brief resurgence by opposing the War of 1812, then collapsed with its last presidential candidate in 1816. Remnants lasted for a few years afterwards. | T3: =IF(H3="", "", VALUE(H3)) | U3: =_xlfn.CONCAT(TEXT(A3,"#"), IF(AND(A3>=10, A3<=19), "th", IF(MOD(A3,10) = 1, "st", IF(MOD(A3,10) = 2, "nd", IF(MOD(A3,10) = 3, "rd", "th"))))) -> 1st | V3: FALSE | W3: John Adams and 8 more | X3: =IF(V3, W3, "") | Y3: =IF(NOT(V3), W3, "") -> John Adams and 8 more | Z3: https://en.wikipedia.org/wiki/1788%E2%80%9389_United_States_presidential_election | AA3: * States had varying methods for choosing presidential electors. In five states, the state legislature chose electors. The other six chose electors through some form involving a popular vote, though in only two states did the choice depend directly on a statewide vote.
A4: 1 | B4: =VLOOKUP(D4,party!A:E,5,0) -> 21 | C4: 1788 | D4: Anti-Administration | G4: 0 | I4: 4 | P4: n/a * | Q4: =IF(IFERROR(VLOOKUP($D4,party!$A:$D,2,0),"")="","",IFERROR(VLOOKUP($D4,party!$A:$D,2,0),"")) -> Not a party. | R4: =IF(IFERROR(VLOOKUP($D4,party!$A:$D,3,0),"")="","",IFERROR(VLOOKUP($D4,party!$A:$D,3,0),"")) -> https://en.wikipedia.org/wiki/Anti-Administration_party | S4: =IF(IFERROR(VLOOKUP($D4,party!$A:$D,4,0),"")="","",IFERROR(VLOOKUP($D4,party!$A:$D,4,0),"")) -> The Anti-Administration party was an informal political faction in the United States led by James Madison and Thomas Jefferson that opposed policies of then Secretary of the Treasury Alexander Hamilton in the first term of U.S. president George Washington. It was not an organized political party, but an unorganized faction. Most members had been Anti-Federalists in 1788, when they opposed ratification of the U.S. Constitution. Although contemporaries often referred to Hamilton's opponents as "Anti-Federalists", that term is now seen as imprecise since several Anti-Administration leaders supported ratification, including Virginia Representative James Madison. | T4: =IF(H4="", "", VALUE(H4)) | U4: =_xlfn.CONCAT(TEXT(A4,"#"), IF(AND(A4>=10, A4<=19), "th", IF(MOD(A4,10) = 1, "st", IF(MOD(A4,10) = 2, "nd", IF(MOD(A4,10) = 3, "rd", "th"))))) -> 1st | V4: FALSE | W4: George Clinton and 1 more | X4: =IF(V4, W4, "") | Y4: =IF(NOT(V4), W4, "") -> George Clinton and 1 more | Z4: https://en.wikipedia.org/wiki/1788%E2%80%9389_United_States_presidential_election | AA4: * States had varying methods for choosing presidential electors. In five states, the state legislature chose electors. The other six chose electors through some form involving a popular vote, though in only two states did the choice depend directly on a statewide vote.
A5: 2 | B5: =VLOOKUP(D5,party!A:E,5,0) -> 1 | C5: 1792 | D5: Independent | E5: George Washington | G5: 28579 | H5: 1 | I5: 132 | P5: 100.0% * | Q5: =IF(IFERROR(VLOOKUP($D5,party!$A:$D,2,0),"")="","",IFERROR(VLOOKUP($D5,party!$A:$D,2,0),"")) -> Not a party. | R5: =IF(IFERROR(VLOOKUP($D5,party!$A:$D,3,0),"")="","",IFERROR(VLOOKUP($D5,party!$A:$D,3,0),"")) -> https://en.wikipedia.org/wiki/Independent_politician | S5: =IF(IFERROR(VLOOKUP($D5,party!$A:$D,4,0),"")="","",IFERROR(VLOOKUP($D5,party!$A:$D,4,0),"")) -> An independent, non-partisan politician or non-affiliated politician is a politician not affiliated with any political party or bureaucratic association. There are numerous reasons why someone may stand for office as an independent. George Washington is the only U.S. president elected as an independent to date. Washington opposed the development of political parties. He feared that partisanship would eventually destroy the country, and famously warned against "the baneful effects of the spirit of party" in his 1796 Farewell Address. | T5: =IF(H5="", "", VALUE(H5)) -> 1 | U5: =_xlfn.CONCAT(TEXT(A5,"#"), IF(AND(A5>=10, A5<=19), "th", IF(MOD(A5,10) = 1, "st", IF(MOD(A5,10) = 2, "nd", IF(MOD(A5,10) = 3, "rd", "th"))))) -> 2nd | V5: TRUE | X5: =IF(V5, W5, "") | Y5: =IF(NOT(V5), W5, "") | Z5: =_xlfn.CONCAT("https://en.wikipedia.org/wiki/", C5, "_United_States_presidential_election") -> https://en.wikipedia.org/wiki/1792_United_States_presidential_election | AA5: * Nine of the 15 states eligible to choose representatives to the electoral college did so by a vote of the state legislature; the remaining six employed some form of popular vote.
A6: 2 | B6: =VLOOKUP(D6,party!A:E,5,0) -> 10 | C6: 1792 | D6: Federalist | G6: 0 | I6: 77 | P6: n/a * | Q6: =IF(IFERROR(VLOOKUP($D6,party!$A:$D,2,0),"")="","",IFERROR(VLOOKUP($D6,party!$A:$D,2,0),"")) | R6: =IF(IFERROR(VLOOKUP($D6,party!$A:$D,3,0),"")="","",IFERROR(VLOOKUP($D6,party!$A:$D,3,0),"")) -> https://en.wikipedia.org/wiki/Federalist_Party | S6: =IF(IFERROR(VLOOKUP($D6,party!$A:$D,4,0),"")="","",IFERROR(VLOOKUP($D6,party!$A:$D,4,0),"")) -> The Federalist Party was a conservative and nationalist American political party and the first political party in the United States. It dominated the national government under Alexander Hamilton from 1789 to 1801. The party was defeated by the Democratic-Republican Party in 1800, and it became a minority party while keeping its stronghold in New England. It made a brief resurgence by opposing the War of 1812, then collapsed with its last presidential candidate in 1816. Remnants lasted for a few years afterwards. | T6: =IF(H6="", "", VALUE(H6)) | U6: =_xlfn.CONCAT(TEXT(A6,"#"), IF(AND(A6>=10, A6<=19), "th", IF(MOD(A6,10) = 1, "st", IF(MOD(A6,10) = 2, "nd", IF(MOD(A6,10) = 3, "rd", "th"))))) -> 2nd | V6: FALSE | W6: John Adams | X6: =IF(V6, W6, "") | Y6: =IF(NOT(V6), W6, "") -> John Adams | Z6: =_xlfn.CONCAT("https://en.wikipedia.org/wiki/", C6, "_United_States_presidential_election") -> https://en.wikipedia.org/wiki/1792_United_States_presidential_election | AA6: * Nine of the 15 states eligible to choose representatives to the electoral college did so by a vote of the state legislature; the remaining six employed some form of popular vote.
A7: 2 | B7: =VLOOKUP(D7,party!A:E,5,0) -> 23 | C7: 1792 | D7: Democratic-Republican | G7: 0 | I7: 55 | P7: n/a * | Q7: =IF(IFERROR(VLOOKUP($D7,party!$A:$D,2,0),"")="","",IFERROR(VLOOKUP($D7,party!$A:$D,2,0),"")) | R7: =IF(IFERROR(VLOOKUP($D7,party!$A:$D,3,0),"")="","",IFERROR(VLOOKUP($D7,party!$A:$D,3,0),"")) -> https://en.wikipedia.org/wiki/Democratic-Republican_Party | S7: =IF(IFERROR(VLOOKUP($D7,party!$A:$D,4,0),"")="","",IFERROR(VLOOKUP($D7,party!$A:$D,4,0),"")) -> The Republican Party, known retroactively as the Democratic-Republican Party (also referred to by historians as the Jeffersonian Republican Party), was an American political party founded by Thomas Jefferson and James Madison in the early 1790s. It championed liberalism, republicanism, individual liberty, equal rights, decentralization, free markets, free trade, and agrarianism. In foreign policy it was hostile to Great Britain and in sympathy with the French Revolution. The party became increasingly dominant after the 1800 elections as the opposing Federalist Party collapsed. | T7: =IF(H7="", "", VALUE(H7)) | U7: =_xlfn.CONCAT(TEXT(A7,"#"), IF(AND(A7>=10, A7<=19), "th", IF(MOD(A7,10) = 1, "st", IF(MOD(A7,10) = 2, "nd", IF(MOD(A7,10) = 3, "rd", "th"))))) -> 2nd | V7: FALSE | W7: George Clinton and 2 more | X7: =IF(V7, W7, "") | Y7: =IF(NOT(V7), W7, "") -> George Clinton and 2 more | Z7: =_xlfn.CONCAT("https://en.wikipedia.org/wiki/", C7, "_United_States_presidential_election") -> https://en.wikipedia.org/wiki/1792_United_States_presidential_election | AA7: * Nine of the 15 states eligible to choose representatives to the electoral college did so by a vote of the state legislature; the remaining six employed some form of popular vote.
A8: 3 | B8: =VLOOKUP(D8,party!A:E,5,0) -> 1 | C8: 1796 | D8: Independent | G8: 0 | I8: 2 | P8: n/a * | Q8: =IF(IFERROR(VLOOKUP($D8,party!$A:$D,2,0),"")="","",IFERROR(VLOOKUP($D8,party!$A:$D,2,0),"")) -> Not a party. | R8: =IF(IFERROR(VLOOKUP($D8,party!$A:$D,3,0),"")="","",IFERROR(VLOOKUP($D8,party!$A:$D,3,0),"")) -> https://en.wikipedia.org/wiki/Independent_politician | S8: =IF(IFERROR(VLOOKUP($D8,party!$A:$D,4,0),"")="","",IFERROR(VLOOKUP($D8,party!$A:$D,4,0),"")) -> An independent, non-partisan politician or non-affiliated politician is a politician not affiliated with any political party or bureaucratic association. There are numerous reasons why someone may stand for office as an independent. George Washington is the only U.S. president elected as an independent to date. Washington opposed the development of political parties. He feared that partisanship would eventually destroy the country, and famously warned against "the baneful effects of the spirit of party" in his 1796 Farewell Address. | T8: =IF(H8="", "", VALUE(H8)) | U8: =_xlfn.CONCAT(TEXT(A8,"#"), IF(AND(A8>=10, A8<=19), "th", IF(MOD(A8,10) = 1, "st", IF(MOD(A8,10) = 2, "nd", IF(MOD(A8,10) = 3, "rd", "th"))))) -> 3rd | V8: FALSE | W8: George Washington | X8: =IF(V8, W8, "") | Y8: =IF(NOT(V8), W8, "") -> George Washington | Z8: =_xlfn.CONCAT("https://en.wikipedia.org/wiki/", C8, "_United_States_presidential_election") -> https://en.wikipedia.org/wiki/1796_United_States_presidential_election | AA8: * Only 9 of the 16 states used any form of popular vote. Those states that did choose electors by popular vote had widely varying restrictions on suffrage via property requirements.
A9: 3 | B9: =VLOOKUP(D9,party!A:E,5,0) -> 10 | C9: 1796 | D9: Federalist | E9: John Adams | G9: 35726 | H9: 0.534 | I9: 152 | J9: 71 | K9: 81 | P9: 53.4% * | Q9: =IF(IFERROR(VLOOKUP($D9,party!$A:$D,2,0),"")="","",IFERROR(VLOOKUP($D9,party!$A:$D,2,0),"")) | R9: =IF(IFERROR(VLOOKUP($D9,party!$A:$D,3,0),"")="","",IFERROR(VLOOKUP($D9,party!$A:$D,3,0),"")) -> https://en.wikipedia.org/wiki/Federalist_Party | S9: =IF(IFERROR(VLOOKUP($D9,party!$A:$D,4,0),"")="","",IFERROR(VLOOKUP($D9,party!$A:$D,4,0),"")) -> The Federalist Party was a conservative and nationalist American political party and the first political party in the United States. It dominated the national government under Alexander Hamilton from 1789 to 1801. The party was defeated by the Democratic-Republican Party in 1800, and it became a minority party while keeping its stronghold in New England. It made a brief resurgence by opposing the War of 1812, then collapsed with its last presidential candidate in 1816. Remnants lasted for a few years afterwards. | T9: =IF(H9="", "", VALUE(H9)) -> 0.534 | U9: =_xlfn.CONCAT(TEXT(A9,"#"), IF(AND(A9>=10, A9<=19), "th", IF(MOD(A9,10) = 1, "st", IF(MOD(A9,10) = 2, "nd", IF(MOD(A9,10) = 3, "rd", "th"))))) -> 3rd | V9: TRUE | W9: Thomas Pinckney and 5 more | X9: =IF(V9, W9, "") -> Thomas Pinckney and 5 more | Y9: =IF(NOT(V9), W9, "") | Z9: =_xlfn.CONCAT("https://en.wikipedia.org/wiki/", C9, "_United_States_presidential_election") -> https://en.wikipedia.org/wiki/1796_United_States_presidential_election | AA9: * Only 9 of the 16 states used any form of popular vote. Those states that did choose electors by popular vote had widely varying restrictions on suffrage via property requirements.
A10: 3 | B10: =VLOOKUP(D10,party!A:E,5,0) -> 23 | C10: 1796 | D10: Democratic-Republican | G10: 31115 | H10: 0.466 | I10: 122 | J10: 68 | K10: 54 | P10: 46.6% * | Q10: =IF(IFERROR(VLOOKUP($D10,party!$A:$D,2,0),"")="","",IFERROR(VLOOKUP($D10,party!$A:$D,2,0),"")) | R10: =IF(IFERROR(VLOOKUP($D10,party!$A:$D,3,0),"")="","",IFERROR(VLOOKUP($D10,party!$A:$D,3,0),"")) -> https://en.wikipedia.org/wiki/Democratic-Republican_Party | S10: =IF(IFERROR(VLOOKUP($D10,party!$A:$D,4,0),"")="","",IFERROR(VLOOKUP($D10,party!$A:$D,4,0),"")) -> The Republican Party, known retroactively as the Democratic-Republican Party (also referred to by historians as the Jeffersonian Republican Party), was an American political party founded by Thomas Jefferson and James Madison in the early 1790s. It championed liberalism, republicanism, individual liberty, equal rights, decentralization, free markets, free trade, and agrarianism. In foreign policy it was hostile to Great Britain and in sympathy with the French Revolution. The party became increasingly dominant after the 1800 elections as the opposing Federalist Party collapsed. | T10: =IF(H10="", "", VALUE(H10)) -> 0.466 | U10: =_xlfn.CONCAT(TEXT(A10,"#"), IF(AND(A10>=10, A10<=19), "th", IF(MOD(A10,10) = 1, "st", IF(MOD(A10,10) = 2, "nd", IF(MOD(A10,10) = 3, "rd", "th"))))) -> 3rd | V10: FALSE | W10: Thomas Jefferson and 4 more | X10: =IF(V10, W10, "") | Y10: =IF(NOT(V10), W10, "") -> Thomas Jefferson and 4 more | Z10: =_xlfn.CONCAT("https://en.wikipedia.org/wiki/", C10, "_United_States_presidential_election") -> https://en.wikipedia.org/wiki/1796_United_States_presidential_election | AA10: * Only 9 of the 16 states used any form of popular vote. Those states that did choose electors by popular vote had widely varying restrictions on suffrage via property requirements.
A11: 4 | B11: =VLOOKUP(D11,party!A:E,5,0) -> 23 | C11: 1800 | D11: Democratic-Republican | E11: Thomas Jefferson | G11: 41330 | H11: 0.614 | I11: 73 | P11: =TEXT(H11,"0.0%") -> 61.4% | Q11: =IF(IFERROR(VLOOKUP($D11,party!$A:$D,2,0),"")="","",IFERROR(VLOOKUP($D11,party!$A:$D,2,0),"")) | R11: =IF(IFERROR(VLOOKUP($D11,party!$A:$D,3,0),"")="","",IFERROR(VLOOKUP($D11,party!$A:$D,3,0),"")) -> https://en.wikipedia.org/wiki/Democratic-Republican_Party | S11: =IF(IFERROR(VLOOKUP($D11,party!$A:$D,4,0),"")="","",IFERROR(VLOOKUP($D11,party!$A:$D,4,0),"")) -> The Republican Party, known retroactively as the Democratic-Republican Party (also referred to by historians as the Jeffersonian Republican Party), was an American political party founded by Thomas Jefferson and James Madison in the early 1790s. It championed liberalism, republicanism, individual liberty, equal rights, decentralization, free markets, free trade, and agrarianism. In foreign policy it was hostile to Great Britain and in sympathy with the French Revolution. The party became increasingly dominant after the 1800 elections as the opposing Federalist Party collapsed. | T11: =IF(H11="", "", VALUE(H11)) -> 0.614 | U11: =_xlfn.CONCAT(TEXT(A11,"#"), IF(AND(A11>=10, A11<=19), "th", IF(MOD(A11,10) = 1, "st", IF(MOD(A11,10) = 2, "nd", IF(MOD(A11,10) = 3, "rd", "th"))))) -> 4th | V11: TRUE | X11: =IF(V11, W11, "") | Y11: =IF(NOT(V11), W11, "") | Z11: =_xlfn.CONCAT("https://en.wikipedia.org/wiki/", C11, "_United_States_presidential_election") -> https://en.wikipedia.org/wiki/1800_United_States_presidential_election
A12: 4 | B12: =VLOOKUP(D12,party!A:E,5,0) -> 10 | C12: 1800 | D12: Federalist | G12: 25952 | H12: 0.386 | I12: 65 | P12: =TEXT(H12,"0.0%") -> 38.6% | Q12: =IF(IFERROR(VLOOKUP($D12,party!$A:$D,2,0),"")="","",IFERROR(VLOOKUP($D12,party!$A:$D,2,0),"")) | R12: =IF(IFERROR(VLOOKUP($D12,party!$A:$D,3,0),"")="","",IFERROR(VLOOKUP($D12,party!$A:$D,3,0),"")) -> https://en.wikipedia.org/wiki/Federalist_Party | S12: =IF(IFERROR(VLOOKUP($D12,party!$A:$D,4,0),"")="","",IFERROR(VLOOKUP($D12,party!$A:$D,4,0),"")) -> The Federalist Party was a conservative and nationalist American political party and the first political party in the United States. It dominated the national government under Alexander Hamilton from 1789 to 1801. The party was defeated by the Democratic-Republican Party in 1800, and it became a minority party while keeping its stronghold in New England. It made a brief resurgence by opposing the War of 1812, then collapsed with its last presidential candidate in 1816. Remnants lasted for a few years afterwards. | T12: =IF(H12="", "", VALUE(H12)) -> 0.386 | U12: =_xlfn.CONCAT(TEXT(A12,"#"), IF(AND(A12>=10, A12<=19), "th", IF(MOD(A12,10) = 1, "st", IF(MOD(A12,10) = 2, "nd", IF(MOD(A12,10) = 3, "rd", "th"))))) -> 4th | V12: FALSE | W12: John Adams | X12: =IF(V12, W12, "") | Y12: =IF(NOT(V12), W12, "") -> John Adams | Z12: =_xlfn.CONCAT("https://en.wikipedia.org/wiki/", C12, "_United_States_presidential_election") -> https://en.wikipedia.org/wiki/1800_United_States_presidential_election
A13: 5 | B13: =VLOOKUP(D13,party!A:E,5,0) -> 23 | C13: 1804 | D13: Democratic-Republican | E13: Thomas Jefferson | G13: 104110 | H13: 0.728 | I13: 162 | P13: =TEXT(H13,"0.0%") -> 72.8% | Q13: =IF(IFERROR(VLOOKUP($D13,party!$A:$D,2,0),"")="","",IFERROR(VLOOKUP($D13,party!$A:$D,2,0),"")) | R13: =IF(IFERROR(VLOOKUP($D13,party!$A:$D,3,0),"")="","",IFERROR(VLOOKUP($D13,party!$A:$D,3,0),"")) -> https://en.wikipedia.org/wiki/Democratic-Republican_Party | S13: =IF(IFERROR(VLOOKUP($D13,party!$A:$D,4,0),"")="","",IFERROR(VLOOKUP($D13,party!$A:$D,4,0),"")) -> The Republican Party, known retroactively as the Democratic-Republican Party (also referred to by historians as the Jeffersonian Republican Party), was an American political party founded by Thomas Jefferson and James Madison in the early 1790s. It championed liberalism, republicanism, individual liberty, equal rights, decentralization, free markets, free trade, and agrarianism. In foreign policy it was hostile to Great Britain and in sympathy with the French Revolution. The party became increasingly dominant after the 1800 elections as the opposing Federalist Party collapsed. | T13: =IF(H13="", "", VALUE(H13)) -> 0.728 | U13: =_xlfn.CONCAT(TEXT(A13,"#"), IF(AND(A13>=10, A13<=19), "th", IF(MOD(A13,10) = 1, "st", IF(MOD(A13,10) = 2, "nd", IF(MOD(A13,10) = 3, "rd", "th"))))) -> 5th | V13: TRUE | X13: =IF(V13, W13, "") | Y13: =IF(NOT(V13), W13, "") | Z13: =_xlfn.CONCAT("https://en.wikipedia.org/wiki/", C13, "_United_States_presidential_election") -> https://en.wikipedia.org/wiki/1804_United_States_presidential_election
A14: 5 | B14: =VLOOKUP(D14,party!A:E,5,0) -> 10 | C14: 1804 | D14: Federalist | G14: 38919 | H14: 0.272 | I14: 14 | P14: =TEXT(H14,"0.0%") -> 27.2% | Q14: =IF(IFERROR(VLOOKUP($D14,party!$A:$D,2,0),"")="","",IFERROR(VLOOKUP($D14,party!$A:$D,2,0),"")) | R14: =IF(IFERROR(VLOOKUP($D14,party!$A:$D,3,0),"")="","",IFERROR(VLOOKUP($D14,party!$A:$D,3,0),"")) -> https://en.wikipedia.org/wiki/Federalist_Party | S14: =IF(IFERROR(VLOOKUP($D14,party!$A:$D,4,0),"")="","",IFERROR(VLOOKUP($D14,party!$A:$D,4,0),"")) -> The Federalist Party was a conservative and nationalist American political party and the first political party in the United States. It dominated the national government under Alexander Hamilton from 1789 to 1801. The party was defeated by the Democratic-Republican Party in 1800, and it became a minority party while keeping its stronghold in New England. It made a brief resurgence by opposing the War of 1812, then collapsed with its last presidential candidate in 1816. Remnants lasted for a few years afterwards. | T14: =IF(H14="", "", VALUE(H14)) -> 0.272 | U14: =_xlfn.CONCAT(TEXT(A14,"#"), IF(AND(A14>=10, A14<=19), "th", IF(MOD(A14,10) = 1, "st", IF(MOD(A14,10) = 2, "nd", IF(MOD(A14,10) = 3, "rd", "th"))))) -> 5th | V14: FALSE | W14: Charles Cotesworth Pinckney | X14: =IF(V14, W14, "") | Y14: =IF(NOT(V14), W14, "") -> Charles Cotesworth Pinckney | Z14: =_xlfn.CONCAT("https://en.wikipedia.org/wiki/", C14, "_United_States_presidential_election") -> https://en.wikipedia.org/wiki/1804_United_States_presidential_election
A15: 6 | B15: =VLOOKUP(D15,party!A:E,5,0) -> 23 | C15: 1808 | D15: Democratic-Republican | E15: James Madison | G15: 124732 | H15: 0.647 | I15: 128 | J15: 122 | K15: 6 | P15: =TEXT(H15,"0.0%") -> 64.7% | Q15: =IF(IFERROR(VLOOKUP($D15,party!$A:$D,2,0),"")="","",IFERROR(VLOOKUP($D15,party!$A:$D,2,0),"")) | R15: =IF(IFERROR(VLOOKUP($D15,party!$A:$D,3,0),"")="","",IFERROR(VLOOKUP($D15,party!$A:$D,3,0),"")) -> https://en.wikipedia.org/wiki/Democratic-Republican_Party | S15: =IF(IFERROR(VLOOKUP($D15,party!$A:$D,4,0),"")="","",IFERROR(VLOOKUP($D15,party!$A:$D,4,0),"")) -> The Republican Party, known retroactively as the Democratic-Republican Party (also referred to by historians as the Jeffersonian Republican Party), was an American political party founded by Thomas Jefferson and James Madison in the early 1790s. It championed liberalism, republicanism, individual liberty, equal rights, decentralization, free markets, free trade, and agrarianism. In foreign policy it was hostile to Great Britain and in sympathy with the French Revolution. The party became increasingly dominant after the 1800 elections as the opposing Federalist Party collapsed. | T15: =IF(H15="", "", VALUE(H15)) -> 0.647 | U15: =_xlfn.CONCAT(TEXT(A15,"#"), IF(AND(A15>=10, A15<=19), "th", IF(MOD(A15,10) = 1, "st", IF(MOD(A15,10) = 2, "nd", IF(MOD(A15,10) = 3, "rd", "th"))))) -> 6th | V15: TRUE | W15: George Clinton | X15: =IF(V15, W15, "") -> George Clinton | Y15: =IF(NOT(V15), W15, "") | Z15: =_xlfn.CONCAT("https://en.wikipedia.org/wiki/", C15, "_United_States_presidential_election") -> https://en.wikipedia.org/wiki/1808_United_States_presidential_election
A16: 6 | B16: =VLOOKUP(D16,party!A:E,5,0) -> 10 | C16: 1808 | D16: Federalist | G16: 62431 | H16: 0.324 | I16: 47 | P16: =TEXT(H16,"0.0%") -> 32.4% | Q16: =IF(IFERROR(VLOOKUP($D16,party!$A:$D,2,0),"")="","",IFERROR(VLOOKUP($D16,party!$A:$D,2,0),"")) | R16: =IF(IFERROR(VLOOKUP($D16,party!$A:$D,3,0),"")="","",IFERROR(VLOOKUP($D16,party!$A:$D,3,0),"")) -> https://en.wikipedia.org/wiki/Federalist_Party | S16: =IF(IFERROR(VLOOKUP($D16,party!$A:$D,4,0),"")="","",IFERROR(VLOOKUP($D16,party!$A:$D,4,0),"")) -> The Federalist Party was a conservative and nationalist American political party and the first political party in the United States. It dominated the national government under Alexander Hamilton from 1789 to 1801. The party was defeated by the Democratic-Republican Party in 1800, and it became a minority party while keeping its stronghold in New England. It made a brief resurgence by opposing the War of 1812, then collapsed with its last presidential candidate in 1816. Remnants lasted for a few years afterwards. | T16: =IF(H16="", "", VALUE(H16)) -> 0.324 | U16: =_xlfn.CONCAT(TEXT(A16,"#"), IF(AND(A16>=10, A16<=19), "th", IF(MOD(A16,10) = 1, "st", IF(MOD(A16,10) = 2, "nd", IF(MOD(A16,10) = 3, "rd", "th"))))) -> 6th | V16: FALSE | W16: Charles Cotesworth Pinckney | X16: =IF(V16, W16, "") | Y16: =IF(NOT(V16), W16, "") -> Charles Cotesworth Pinckney | Z16: =_xlfn.CONCAT("https://en.wikipedia.org/wiki/", C16, "_United_States_presidential_election") -> https://en.wikipedia.org/wiki/1808_United_States_presidential_election
A17: 7 | B17: =VLOOKUP(D17,party!A:E,5,0) -> 23 | C17: 1812 | D17: Democratic-Republican | E17: James Madison | G17: 140431 | H17: 0.504 | I17: 128 | P17: =TEXT(H17,"0.0%") -> 50.4% | Q17: =IF(IFERROR(VLOOKUP($D17,party!$A:$D,2,0),"")="","",IFERROR(VLOOKUP($D17,party!$A:$D,2,0),"")) | R17: =IF(IFERROR(VLOOKUP($D17,party!$A:$D,3,0),"")="","",IFERROR(VLOOKUP($D17,party!$A:$D,3,0),"")) -> https://en.wikipedia.org/wiki/Democratic-Republican_Party | S17: =IF(IFERROR(VLOOKUP($D17,party!$A:$D,4,0),"")="","",IFERROR(VLOOKUP($D17,party!$A:$D,4,0),"")) -> The Republican Party, known retroactively as the Democratic-Republican Party (also referred to by historians as the Jeffersonian Republican Party), was an American political party founded by Thomas Jefferson and James Madison in the early 1790s. It championed liberalism, republicanism, individual liberty, equal rights, decentralization, free markets, free trade, and agrarianism. In foreign policy it was hostile to Great Britain and in sympathy with the French Revolution. The party became increasingly dominant after the 1800 elections as the opposing Federalist Party collapsed. | T17: =IF(H17="", "", VALUE(H17)) -> 0.504 | U17: =_xlfn.CONCAT(TEXT(A17,"#"), IF(AND(A17>=10, A17<=19), "th", IF(MOD(A17,10) = 1, "st", IF(MOD(A17,10) = 2, "nd", IF(MOD(A17,10) = 3, "rd", "th"))))) -> 7th | V17: TRUE | X17: =IF(V17, W17, "") | Y17: =IF(NOT(V17), W17, "") | Z17: =_xlfn.CONCAT("https://en.wikipedia.org/wiki/", C17, "_United_States_presidential_election") -> https://en.wikipedia.org/wiki/1812_United_States_presidential_election
A18: 7 | B18: =VLOOKUP(D18,party!A:E,5,0) -> 22 | C18: 1812 | D18: Democratic-Republican / Federalist | G18: 132781 | H18: 0.476 | I18: 89 | P18: =TEXT(H18,"0.0%") -> 47.6% | Q18: =IF(IFERROR(VLOOKUP($D18,party!$A:$D,2,0),"")="","",IFERROR(VLOOKUP($D18,party!$A:$D,2,0),"")) -> Not a party. | R18: =IF(IFERROR(VLOOKUP($D18,party!$A:$D,3,0),"")="","",IFERROR(VLOOKUP($D18,party!$A:$D,3,0),"")) -> https://en.wikipedia.org/wiki/1812_United_States_presidential_election | S18: =IF(IFERROR(VLOOKUP($D18,party!$A:$D,4,0),"")="","",IFERROR(VLOOKUP($D18,party!$A:$D,4,0),"")) -> While commonly labeled as the Federalist candidate, Clinton technically ran as a Democratic-Republican and was not nominated by the Federalist party itself, the latter simply deciding not to field a candidate. This did not prevent endorsements from state Federalist parties (such as in Pennsylvania), but he received the endorsement from the New York state Democratic-Republicans as well. | T18: =IF(H18="", "", VALUE(H18)) -> 0.476 | U18: =_xlfn.CONCAT(TEXT(A18,"#"), IF(AND(A18>=10, A18<=19), "th", IF(MOD(A18,10) = 1, "st", IF(MOD(A18,10) = 2, "nd", IF(MOD(A18,10) = 3, "rd", "th"))))) -> 7th | V18: FALSE | W18: DeWitt Clinton | X18: =IF(V18, W18, "") | Y18: =IF(NOT(V18), W18, "") -> DeWitt Clinton | Z18: =_xlfn.CONCAT("https://en.wikipedia.org/wiki/", C18, "_United_States_presidential_election") -> https://en.wikipedia.org/wiki/1812_United_States_presidential_election
A19: 8 | B19: =VLOOKUP(D19,party!A:E,5,0) -> 23 | C19: 1816 | D19: Democratic-Republican | E19: James Monroe | G19: 76592 | H19: 0.682 | I19: 183 | P19: =TEXT(H19,"0.0%") -> 68.2% | Q19: =IF(IFERROR(VLOOKUP($D19,party!$A:$D,2,0),"")="","",IFERROR(VLOOKUP($D19,party!$A:$D,2,0),"")) | R19: =IF(IFERROR(VLOOKUP($D19,party!$A:$D,3,0),"")="","",IFERROR(VLOOKUP($D19,party!$A:$D,3,0),"")) -> https://en.wikipedia.org/wiki/Democratic-Republican_Party | S19: =IF(IFERROR(VLOOKUP($D19,party!$A:$D,4,0),"")="","",IFERROR(VLOOKUP($D19,party!$A:$D,4,0),"")) -> The Republican Party, known retroactively as the Democratic-Republican Party (also referred to by historians as the Jeffersonian Republican Party), was an American political party founded by Thomas Jefferson and James Madison in the early 1790s. It championed liberalism, republicanism, individual liberty, equal rights, decentralization, free markets, free trade, and agrarianism. In foreign policy it was hostile to Great Britain and in sympathy with the French Revolution. The party became increasingly dominant after the 1800 elections as the opposing Federalist Party collapsed. | T19: =IF(H19="", "", VALUE(H19)) -> 0.682 | U19: =_xlfn.CONCAT(TEXT(A19,"#"), IF(AND(A19>=10, A19<=19), "th", IF(MOD(A19,10) = 1, "st", IF(MOD(A19,10) = 2, "nd", IF(MOD(A19,10) = 3, "rd", "th"))))) -> 8th | V19: TRUE | X19: =IF(V19, W19, "") | Y19: =IF(NOT(V19), W19, "") | Z19: =_xlfn.CONCAT("https://en.wikipedia.org/wiki/", C19, "_United_States_presidential_election") -> https://en.wikipedia.org/wiki/1816_United_States_presidential_election
A20: 8 | B20: =VLOOKUP(D20,party!A:E,5,0) -> 10 | C20: 1816 | D20: Federalist | G20: 34740 | H20: 0.309 | I20: 34 | P20: =TEXT(H20,"0.0%") -> 30.9% | Q20: =IF(IFERROR(VLOOKUP($D20,party!$A:$D,2,0),"")="","",IFERROR(VLOOKUP($D20,party!$A:$D,2,0),"")) | R20: =IF(IFERROR(VLOOKUP($D20,party!$A:$D,3,0),"")="","",IFERROR(VLOOKUP($D20,party!$A:$D,3,0),"")) -> https://en.wikipedia.org/wiki/Federalist_Party | S20: =IF(IFERROR(VLOOKUP($D20,party!$A:$D,4,0),"")="","",IFERROR(VLOOKUP($D20,party!$A:$D,4,0),"")) -> The Federalist Party was a conservative and nationalist American political party and the first political party in the United States. It dominated the national government under Alexander Hamilton from 1789 to 1801. The party was defeated by the Democratic-Republican Party in 1800, and it became a minority party while keeping its stronghold in New England. It made a brief resurgence by opposing the War of 1812, then collapsed with its last presidential candidate in 1816. Remnants lasted for a few years afterwards. | T20: =IF(H20="", "", VALUE(H20)) -> 0.309 | U20: =_xlfn.CONCAT(TEXT(A20,"#"), IF(AND(A20>=10, A20<=19), "th", IF(MOD(A20,10) = 1, "st", IF(MOD(A20,10) = 2, "nd", IF(MOD(A20,10) = 3, "rd", "th"))))) -> 8th | V20: FALSE | W20: Rufus King | X20: =IF(V20, W20, "") | Y20: =IF(NOT(V20), W20, "") -> Rufus King | Z20: =_xlfn.CONCAT("https://en.wikipedia.org/wiki/", C20, "_United_States_presidential_election") -> https://en.wikipedia.org/wiki/1816_United_States_presidential_election
A21: 9 | B21: =VLOOKUP(D21,party!A:E,5,0) -> 23 | C21: 1820 | D21: Democratic-Republican | E21: James Monroe | G21: 87343 | H21: 0.806 | I21: 232 | P21: =TEXT(H21,"0.0%") -> 80.6% | Q21: =IF(IFERROR(VLOOKUP($D21,party!$A:$D,2,0),"")="","",IFERROR(VLOOKUP($D21,party!$A:$D,2,0),"")) | R21: =IF(IFERROR(VLOOKUP($D21,party!$A:$D,3,0),"")="","",IFERROR(VLOOKUP($D21,party!$A:$D,3,0),"")) -> https://en.wikipedia.org/wiki/Democratic-Republican_Party | S21: =IF(IFERROR(VLOOKUP($D21,party!$A:$D,4,0),"")="","",IFERROR(VLOOKUP($D21,party!$A:$D,4,0),"")) -> The Republican Party, known retroactively as the Democratic-Republican Party (also referred to by historians as the Jeffersonian Republican Party), was an American political party founded by Thomas Jefferson and James Madison in the early 1790s. It championed liberalism, republicanism, individual liberty, equal rights, decentralization, free markets, free trade, and agrarianism. In foreign policy it was hostile to Great Britain and in sympathy with the French Revolution. The party became increasingly dominant after the 1800 elections as the opposing Federalist Party collapsed. | T21: =IF(H21="", "", VALUE(H21)) -> 0.806 | U21: =_xlfn.CONCAT(TEXT(A21,"#"), IF(AND(A21>=10, A21<=19), "th", IF(MOD(A21,10) = 1, "st", IF(MOD(A21,10) = 2, "nd", IF(MOD(A21,10) = 3, "rd", "th"))))) -> 9th | V21: TRUE | W21: John Quincy Adams | X21: =IF(V21, W21, "") -> John Quincy Adams | Y21: =IF(NOT(V21), W21, "") | Z21: =_xlfn.CONCAT("https://en.wikipedia.org/wiki/", C21, "_United_States_presidential_election") -> https://en.wikipedia.org/wiki/1820_United_States_presidential_election
A22: 10 | B22: =VLOOKUP(D22,party!A:E,5,0) -> 12 | C22: 1824 | D22: Democratic-Republican (Adams faction) | E22: John Quincy Adams | G22: 113122 | H22: 0.309 | I22: 84 | P22: =TEXT(H22,"0.0%") -> 30.9% | Q22: =IF(IFERROR(VLOOKUP($D22,party!$A:$D,2,0),"")="","",IFERROR(VLOOKUP($D22,party!$A:$D,2,0),"")) -> Not a party. | R22: =IF(IFERROR(VLOOKUP($D22,party!$A:$D,3,0),"")="","",IFERROR(VLOOKUP($D22,party!$A:$D,3,0),"")) -> https://en.wikipedia.org/wiki/1824_United_States_presidential_election | S22: =IF(IFERROR(VLOOKUP($D22,party!$A:$D,4,0),"")="","",IFERROR(VLOOKUP($D22,party!$A:$D,4,0),"")) -> The Democratic-Republican Party had won six consecutive presidential elections and by 1824 was the only national political party. However, as the election approached, the presence of multiple viable candidates resulted in there being multiple nominations by the contending factions, signaling the splintering of the party and an end to the Era of Good Feelings, as well as the First Party System. Adams won New England, Jackson and Adams split the mid-Atlantic states, Jackson and Clay split the Western states, and Jackson and Crawford split the Southern states. | T22: =IF(H22="", "", VALUE(H22)) -> 0.309 | U22: =_xlfn.CONCAT(TEXT(A22,"#"), IF(AND(A22>=10, A22<=19), "th", IF(MOD(A22,10) = 1, "st", IF(MOD(A22,10) = 2, "nd", IF(MOD(A22,10) = 3, "rd", "th"))))) -> 10th | V22: TRUE | X22: =IF(V22, W22, "") | Y22: =IF(NOT(V22), W22, "") | Z22: =_xlfn.CONCAT("https://en.wikipedia.org/wiki/", C22, "_United_States_presidential_election") -> https://en.wikipedia.org/wiki/1824_United_States_presidential_election | AA22: Since no candidate received a majority of the electoral vote, the House of Representatives elected the president. In the House, 13 state delegations voted for Adams, seven for Jackson, and four for Crawford.
A23: 10 | B23: =VLOOKUP(D23,party!A:E,5,0) -> 25 | C23: 1824 | D23: Democratic-Republican (Jackson faction) | G23: 151271 | H23: 0.414 | I23: 99 | P23: =TEXT(H23,"0.0%") -> 41.4% | Q23: =IF(IFERROR(VLOOKUP($D23,party!$A:$D,2,0),"")="","",IFERROR(VLOOKUP($D23,party!$A:$D,2,0),"")) -> Not a party. | R23: =IF(IFERROR(VLOOKUP($D23,party!$A:$D,3,0),"")="","",IFERROR(VLOOKUP($D23,party!$A:$D,3,0),"")) -> https://en.wikipedia.org/wiki/1824_United_States_presidential_election | S23: =IF(IFERROR(VLOOKUP($D23,party!$A:$D,4,0),"")="","",IFERROR(VLOOKUP($D23,party!$A:$D,4,0),"")) -> The Democratic-Republican Party had won six consecutive presidential elections and by 1824 was the only national political party. However, as the election approached, the presence of multiple viable candidates resulted in there being multiple nominations by the contending factions, signaling the splintering of the party and an end to the Era of Good Feelings, as well as the First Party System. Adams won New England, Jackson and Adams split the mid-Atlantic states, Jackson and Clay split the Western states, and Jackson and Crawford split the Southern states. | T23: =IF(H23="", "", VALUE(H23)) -> 0.414 | U23: =_xlfn.CONCAT(TEXT(A23,"#"), IF(AND(A23>=10, A23<=19), "th", IF(MOD(A23,10) = 1, "st", IF(MOD(A23,10) = 2, "nd", IF(MOD(A23,10) = 3, "rd", "th"))))) -> 10th | V23: FALSE | W23: Andrew Jackson | X23: =IF(V23, W23, "") | Y23: =IF(NOT(V23), W23, "") -> Andrew Jackson | Z23: =_xlfn.CONCAT("https://en.wikipedia.org/wiki/", C23, "_United_States_presidential_election") -> https://en.wikipedia.org/wiki/1824_United_States_presidential_election | AA23: Since no candidate received a majority of the electoral vote, the House of Representatives elected the president. In the House, 13 state delegations voted for Adams, seven for Jackson, and four for Crawford.
A24: 10 | B24: =VLOOKUP(D24,party!A:E,5,0) -> 24 | C24: 1824 | D24: Democratic-Republican (Crawford faction) | G24: 40856 | H24: 0.112 | I24: 40 | P24: =TEXT(H24,"0.0%") -> 11.2% | Q24: =IF(IFERROR(VLOOKUP($D24,party!$A:$D,2,0),"")="","",IFERROR(VLOOKUP($D24,party!$A:$D,2,0),"")) -> Not a party. | R24: =IF(IFERROR(VLOOKUP($D24,party!$A:$D,3,0),"")="","",IFERROR(VLOOKUP($D24,party!$A:$D,3,0),"")) -> https://en.wikipedia.org/wiki/1824_United_States_presidential_election | S24: =IF(IFERROR(VLOOKUP($D24,party!$A:$D,4,0),"")="","",IFERROR(VLOOKUP($D24,party!$A:$D,4,0),"")) -> The Democratic-Republican Party had won six consecutive presidential elections and by 1824 was the only national political party. However, as the election approached, the presence of multiple viable candidates resulted in there being multiple nominations by the contending factions, signaling the splintering of the party and an end to the Era of Good Feelings, as well as the First Party System. Adams won New England, Jackson and Adams split the mid-Atlantic states, Jackson and Clay split the Western states, and Jackson and Crawford split the Southern states. | T24: =IF(H24="", "", VALUE(H24)) -> 0.112 | U24: =_xlfn.CONCAT(TEXT(A24,"#"), IF(AND(A24>=10, A24<=19), "th", IF(MOD(A24,10) = 1, "st", IF(MOD(A24,10) = 2, "nd", IF(MOD(A24,10) = 3, "rd", "th"))))) -> 10th | V24: FALSE | W24: William H. Crawford | X24: =IF(V24, W24, "") | Y24: =IF(NOT(V24), W24, "") -> William H. Crawford | Z24: =_xlfn.CONCAT("https://en.wikipedia.org/wiki/", C24, "_United_States_presidential_election") -> https://en.wikipedia.org/wiki/1824_United_States_presidential_election | AA24: Since no candidate received a majority of the electoral vote, the House of Representatives elected the president. In the House, 13 state delegations voted for Adams, seven for Jackson, and four for Crawford.
A25: 10 | B25: =VLOOKUP(D25,party!A:E,5,0) -> 11 | C25: 1824 | D25: Democratic-Republican (Clay faction) | G25: 47531 | H25: 0.13 | I25: 38 | P25: =TEXT(H25,"0.0%") -> 13.0% | Q25: =IF(IFERROR(VLOOKUP($D25,party!$A:$D,2,0),"")="","",IFERROR(VLOOKUP($D25,party!$A:$D,2,0),"")) -> Not a party. | R25: =IF(IFERROR(VLOOKUP($D25,party!$A:$D,3,0),"")="","",IFERROR(VLOOKUP($D25,party!$A:$D,3,0),"")) -> https://en.wikipedia.org/wiki/1824_United_States_presidential_election | S25: =IF(IFERROR(VLOOKUP($D25,party!$A:$D,4,0),"")="","",IFERROR(VLOOKUP($D25,party!$A:$D,4,0),"")) -> The Democratic-Republican Party had won six consecutive presidential elections and by 1824 was the only national political party. However, as the election approached, the presence of multiple viable candidates resulted in there being multiple nominations by the contending factions, signaling the splintering of the party and an end to the Era of Good Feelings, as well as the First Party System. Adams won New England, Jackson and Adams split the mid-Atlantic states, Jackson and Clay split the Western states, and Jackson and Crawford split the Southern states. | T25: =IF(H25="", "", VALUE(H25)) -> 0.13 | U25: =_xlfn.CONCAT(TEXT(A25,"#"), IF(AND(A25>=10, A25<=19), "th", IF(MOD(A25,10) = 1, "st", IF(MOD(A25,10) = 2, "nd", IF(MOD(A25,10) = 3, "rd", "th"))))) -> 10th | V25: FALSE | W25: Henry Clay | X25: =IF(V25, W25, "") | Y25: =IF(NOT(V25), W25, "") -> Henry Clay | Z25: =_xlfn.CONCAT("https://en.wikipedia.org/wiki/", C25, "_United_States_presidential_election") -> https://en.wikipedia.org/wiki/1824_United_States_presidential_election | AA25: Since no candidate received a majority of the electoral vote, the House of Representatives elected the president. In the House, 13 state delegations voted for Adams, seven for Jackson, and four for Crawford.
A26: 11 | B26: =VLOOKUP(D26,party!A:E,5,0) -> 26 | C26: 1828 | D26: Democratic | E26: Andrew Jackson | G26: 642553 | H26: 0.56 | I26: 178 | P26: =TEXT(H26,"0.0%") -> 56.0% | Q26: =IF(IFERROR(VLOOKUP($D26,party!$A:$D,2,0),"")="","",IFERROR(VLOOKUP($D26,party!$A:$D,2,0),"")) | R26: =IF(IFERROR(VLOOKUP($D26,party!$A:$D,3,0),"")="","",IFERROR(VLOOKUP($D26,party!$A:$D,3,0),"")) -> https://en.wikipedia.org/wiki/Democratic_Party_(United_States) | S26: =IF(IFERROR(VLOOKUP($D26,party!$A:$D,4,0),"")="","",IFERROR(VLOOKUP($D26,party!$A:$D,4,0),"")) -> The Democratic Party is one of the two major contemporary political parties in the United States. Since the late 1850s, its main political rival has been the Republican Party; the two parties have since dominated American politics. The Democratic Party was founded in 1828. The Democratic Party is the world's oldest active political party. It initially supported expansive presidential power, the interests of slave states, agrarianism, and geographical expansionism, while opposing a national bank and high tariffs. It split in 1860 over slavery and won the presidency only twice between 1860 and 1912, although it won the popular vote two more times in that period. | T26: =IF(H26="", "", VALUE(H26)) -> 0.56 | U26: =_xlfn.CONCAT(TEXT(A26,"#"), IF(AND(A26>=10, A26<=19), "th", IF(MOD(A26,10) = 1, "st", IF(MOD(A26,10) = 2, "nd", IF(MOD(A26,10) = 3, "rd", "th"))))) -> 11th | V26: TRUE | X26: =IF(V26, W26, "") | Y26: =IF(NOT(V26), W26, "") | Z26: =_xlfn.CONCAT("https://en.wikipedia.org/wiki/", C26, "_United_States_presidential_election") -> https://en.wikipedia.org/wiki/1828_United_States_presidential_election
A27: 11 | B27: =VLOOKUP(D27,party!A:E,5,0) -> 13 | C27: 1828 | D27: National Republican | G27: 500897 | H27: 0.436 | I27: 83 | P27: =TEXT(H27,"0.0%") -> 43.6% | Q27: =IF(IFERROR(VLOOKUP($D27,party!$A:$D,2,0),"")="","",IFERROR(VLOOKUP($D27,party!$A:$D,2,0),"")) | R27: =IF(IFERROR(VLOOKUP($D27,party!$A:$D,3,0),"")="","",IFERROR(VLOOKUP($D27,party!$A:$D,3,0),"")) -> https://en.wikipedia.org/wiki/National_Republican_Party | S27: =IF(IFERROR(VLOOKUP($D27,party!$A:$D,4,0),"")="","",IFERROR(VLOOKUP($D27,party!$A:$D,4,0),"")) -> The National Republican Party, also known as the Anti-Jacksonian Party or simply Republicans, was a political party in the United States which evolved from a conservative-leaning faction of the Democratic-Republican Party that supported John Quincy Adams in the 1824 presidential election. After the 1832 election, opponents of Jackson coalesced into the Whig Party. National Republicans, Anti-Masons and others joined the new party. | T27: =IF(H27="", "", VALUE(H27)) -> 0.436 | U27: =_xlfn.CONCAT(TEXT(A27,"#"), IF(AND(A27>=10, A27<=19), "th", IF(MOD(A27,10) = 1, "st", IF(MOD(A27,10) = 2, "nd", IF(MOD(A27,10) = 3, "rd", "th"))))) -> 11th | V27: FALSE | W27: John Quincy Adams | X27: =IF(V27, W27, "") | Y27: =IF(NOT(V27), W27, "") -> John Quincy Adams | Z27: =_xlfn.CONCAT("https://en.wikipedia.org/wiki/", C27, "_United_States_presidential_election") -> https://en.wikipedia.org/wiki/1828_United_States_presidential_election
A28: 12 | B28: =VLOOKUP(D28,party!A:E,5,0) -> 26 | C28: 1832 | D28: Democratic | E28: Andrew Jackson | G28: 701780 | H28: 0.542 | I28: 219 | P28: =TEXT(H28,"0.0%") -> 54.2% | Q28: =IF(IFERROR(VLOOKUP($D28,party!$A:$D,2,0),"")="","",IFERROR(VLOOKUP($D28,party!$A:$D,2,0),"")) | R28: =IF(IFERROR(VLOOKUP($D28,party!$A:$D,3,0),"")="","",IFERROR(VLOOKUP($D28,party!$A:$D,3,0),"")) -> https://en.wikipedia.org/wiki/Democratic_Party_(United_States) | S28: =IF(IFERROR(VLOOKUP($D28,party!$A:$D,4,0),"")="","",IFERROR(VLOOKUP($D28,party!$A:$D,4,0),"")) -> The Democratic Party is one of the two major contemporary political parties in the United States. Since the late 1850s, its main political rival has been the Republican Party; the two parties have since dominated American politics. The Democratic Party was founded in 1828. The Democratic Party is the world's oldest active political party. It initially supported expansive presidential power, the interests of slave states, agrarianism, and geographical expansionism, while opposing a national bank and high tariffs. It split in 1860 over slavery and won the presidency only twice between 1860 and 1912, although it won the popular vote two more times in that period. | T28: =IF(H28="", "", VALUE(H28)) -> 0.542 | U28: =_xlfn.CONCAT(TEXT(A28,"#"), IF(AND(A28>=10, A28<=19), "th", IF(MOD(A28,10) = 1, "st", IF(MOD(A28,10) = 2, "nd", IF(MOD(A28,10) = 3, "rd", "th"))))) -> 12th | V28: TRUE | X28: =IF(V28, W28, "") | Y28: =IF(NOT(V28), W28, "") | Z28: =_xlfn.CONCAT("https://en.wikipedia.org/wiki/", C28, "_United_States_presidential_election") -> https://en.wikipedia.org/wiki/1832_United_States_presidential_election
A29: 12 | B29: =VLOOKUP(D29,party!A:E,5,0) -> 13 | C29: 1832 | D29: National Republican | G29: 484205 | H29: 0.374 | I29: 49 | P29: =TEXT(H29,"0.0%") -> 37.4% | Q29: =IF(IFERROR(VLOOKUP($D29,party!$A:$D,2,0),"")="","",IFERROR(VLOOKUP($D29,party!$A:$D,2,0),"")) | R29: =IF(IFERROR(VLOOKUP($D29,party!$A:$D,3,0),"")="","",IFERROR(VLOOKUP($D29,party!$A:$D,3,0),"")) -> https://en.wikipedia.org/wiki/National_Republican_Party | S29: =IF(IFERROR(VLOOKUP($D29,party!$A:$D,4,0),"")="","",IFERROR(VLOOKUP($D29,party!$A:$D,4,0),"")) -> The National Republican Party, also known as the Anti-Jacksonian Party or simply Republicans, was a political party in the United States which evolved from a conservative-leaning faction of the Democratic-Republican Party that supported John Quincy Adams in the 1824 presidential election. After the 1832 election, opponents of Jackson coalesced into the Whig Party. National Republicans, Anti-Masons and others joined the new party. | T29: =IF(H29="", "", VALUE(H29)) -> 0.374 | U29: =_xlfn.CONCAT(TEXT(A29,"#"), IF(AND(A29>=10, A29<=19), "th", IF(MOD(A29,10) = 1, "st", IF(MOD(A29,10) = 2, "nd", IF(MOD(A29,10) = 3, "rd", "th"))))) -> 12th | V29: FALSE | W29: Henry Clay | X29: =IF(V29, W29, "") | Y29: =IF(NOT(V29), W29, "") -> Henry Clay | Z29: =_xlfn.CONCAT("https://en.wikipedia.org/wiki/", C29, "_United_States_presidential_election") -> https://en.wikipedia.org/wiki/1832_United_States_presidential_election
A30: 12 | B30: =VLOOKUP(D30,party!A:E,5,0) -> 2 | C30: 1832 | D30: Nullifier | G30: 0 | I30: 11 | P30: n/a * | Q30: =IF(IFERROR(VLOOKUP($D30,party!$A:$D,2,0),"")="","",IFERROR(VLOOKUP($D30,party!$A:$D,2,0),"")) | R30: =IF(IFERROR(VLOOKUP($D30,party!$A:$D,3,0),"")="","",IFERROR(VLOOKUP($D30,party!$A:$D,3,0),"")) -> https://en.wikipedia.org/wiki/Nullifier_Party | S30: =IF(IFERROR(VLOOKUP($D30,party!$A:$D,4,0),"")="","",IFERROR(VLOOKUP($D30,party!$A:$D,4,0),"")) -> The Nullifier Party was an American political party based in South Carolina in the 1830s. Considered an early American third party, it was started by John C. Calhoun in 1828. The Nullifier Party was a states' rights, pro-slavery party that supported strict constructionism with regards to the U.S. government's enumerated powers, holding that states could nullify federal laws within their borders. It narrowly missed claiming the unofficial title of being the first ever third party to be created within the United States—that title belongs to the Anti-Masonic Party, which was created in New York in February 1828. | T30: =IF(H30="", "", VALUE(H30)) | U30: =_xlfn.CONCAT(TEXT(A30,"#"), IF(AND(A30>=10, A30<=19), "th", IF(MOD(A30,10) = 1, "st", IF(MOD(A30,10) = 2, "nd", IF(MOD(A30,10) = 3, "rd", "th"))))) -> 12th | V30: FALSE | W30: John Floyd | X30: =IF(V30, W30, "") | Y30: =IF(NOT(V30), W30, "") -> John Floyd | Z30: =_xlfn.CONCAT("https://en.wikipedia.org/wiki/", C30, "_United_States_presidential_election") -> https://en.wikipedia.org/wiki/1832_United_States_presidential_election | AA30: * All the electoral votes came from South Carolina, where the electors were chosen by the legislature and not by popular vote.
A31: 12 | B31: =VLOOKUP(D31,party!A:E,5,0) -> 14 | C31: 1832 | D31: Anti-Masonic | G31: 100715 | H31: 0.078 | I31: 7 | P31: =TEXT(H31,"0.0%") -> 7.8% | Q31: =IF(IFERROR(VLOOKUP($D31,party!$A:$D,2,0),"")="","",IFERROR(VLOOKUP($D31,party!$A:$D,2,0),"")) | R31: =IF(IFERROR(VLOOKUP($D31,party!$A:$D,3,0),"")="","",IFERROR(VLOOKUP($D31,party!$A:$D,3,0),"")) -> https://en.wikipedia.org/wiki/Anti-Masonic_Party | S31: =IF(IFERROR(VLOOKUP($D31,party!$A:$D,4,0),"")="","",IFERROR(VLOOKUP($D31,party!$A:$D,4,0),"")) -> The Anti-Masonic Party was the earliest third party in the United States. Formally a single-issue party, it strongly opposed Freemasonry in the United States. It was active from the late 1820s, especially in the Northeast, and later attempted to become a major party by expanding its platform to take positions on other issues. It declined quickly after 1832 as most members joined the new Whig Party; it disappeared after 1838. | T31: =IF(H31="", "", VALUE(H31)) -> 0.078 | U31: =_xlfn.CONCAT(TEXT(A31,"#"), IF(AND(A31>=10, A31<=19), "th", IF(MOD(A31,10) = 1, "st", IF(MOD(A31,10) = 2, "nd", IF(MOD(A31,10) = 3, "rd", "th"))))) -> 12th | V31: FALSE | W31: William Wirt | X31: =IF(V31, W31, "") | Y31: =IF(NOT(V31), W31, "") -> William Wirt | Z31: =_xlfn.CONCAT("https://en.wikipedia.org/wiki/", C31, "_United_States_presidential_election") -> https://en.wikipedia.org/wiki/1832_United_States_presidential_election
A32: 13 | B32: =VLOOKUP(D32,party!A:E,5,0) -> 26 | C32: 1836 | D32: Democratic | E32: Martin Van Buren | G32: 763291 | H32: 0.508 | I32: 170 | P32: =TEXT(H32,"0.0%") -> 50.8% | Q32: =IF(IFERROR(VLOOKUP($D32,party!$A:$D,2,0),"")="","",IFERROR(VLOOKUP($D32,party!$A:$D,2,0),"")) | R32: =IF(IFERROR(VLOOKUP($D32,party!$A:$D,3,0),"")="","",IFERROR(VLOOKUP($D32,party!$A:$D,3,0),"")) -> https://en.wikipedia.org/wiki/Democratic_Party_(United_States) | S32: =IF(IFERROR(VLOOKUP($D32,party!$A:$D,4,0),"")="","",IFERROR(VLOOKUP($D32,party!$A:$D,4,0),"")) -> The Democratic Party is one of the two major contemporary political parties in the United States. Since the late 1850s, its main political rival has been the Republican Party; the two parties have since dominated American politics. The Democratic Party was founded in 1828. The Democratic Party is the world's oldest active political party. It initially supported expansive presidential power, the interests of slave states, agrarianism, and geographical expansionism, while opposing a national bank and high tariffs. It split in 1860 over slavery and won the presidency only twice between 1860 and 1912, although it won the popular vote two more times in that period. | T32: =IF(H32="", "", VALUE(H32)) -> 0.508 | U32: =_xlfn.CONCAT(TEXT(A32,"#"), IF(AND(A32>=10, A32<=19), "th", IF(MOD(A32,10) = 1, "st", IF(MOD(A32,10) = 2, "nd", IF(MOD(A32,10) = 3, "rd", "th"))))) -> 13th | V32: TRUE | X32: =IF(V32, W32, "") | Y32: =IF(NOT(V32), W32, "") | Z32: =_xlfn.CONCAT("https://en.wikipedia.org/wiki/", C32, "_United_States_presidential_election") -> https://en.wikipedia.org/wiki/1836_United_States_presidential_election
A33: 13 | B33: =VLOOKUP(D33,party!A:E,5,0) -> 15 | C33: 1836 | D33: Whig | G33: 737215 | H33: 0.49 | I33: 124 | P33: =TEXT(H33,"0.0%") -> 49.0% | Q33: =IF(IFERROR(VLOOKUP($D33,party!$A:$D,2,0),"")="","",IFERROR(VLOOKUP($D33,party!$A:$D,2,0),"")) | R33: =IF(IFERROR(VLOOKUP($D33,party!$A:$D,3,0),"")="","",IFERROR(VLOOKUP($D33,party!$A:$D,3,0),"")) -> https://en.wikipedia.org/wiki/Whig_Party_(United_States) | S33: =IF(IFERROR(VLOOKUP($D33,party!$A:$D,4,0),"")="","",IFERROR(VLOOKUP($D33,party!$A:$D,4,0),"")) -> The Whig Party was a mid-19th century political party in the United States. Alongside the Democratic Party, it was one of two major parties between the late 1830s and the early 1850s and part of the Second Party System. The Whigs emerged in the 1830s in opposition to President Andrew Jackson, pulling together former members of the National Republican Party, the Anti-Masonic Party, and disaffected Democrats. | T33: =IF(H33="", "", VALUE(H33)) -> 0.49 | U33: =_xlfn.CONCAT(TEXT(A33,"#"), IF(AND(A33>=10, A33<=19), "th", IF(MOD(A33,10) = 1, "st", IF(MOD(A33,10) = 2, "nd", IF(MOD(A33,10) = 3, "rd", "th"))))) -> 13th | V33: FALSE | W33: William Henry Harrison and 3 more | X33: =IF(V33, W33, "") | Y33: =IF(NOT(V33), W33, "") -> William Henry Harrison and 3 more | Z33: =_xlfn.CONCAT("https://en.wikipedia.org/wiki/", C33, "_United_States_presidential_election") -> https://en.wikipedia.org/wiki/1836_United_States_presidential_election
A34: 14 | B34: =VLOOKUP(D34,party!A:E,5,0) -> 26 | C34: 1840 | D34: Democratic | G34: 1128854 | H34: 0.468 | I34: 60 | P34: =TEXT(H34,"0.0%") -> 46.8% | Q34: =IF(IFERROR(VLOOKUP($D34,party!$A:$D,2,0),"")="","",IFERROR(VLOOKUP($D34,party!$A:$D,2,0),"")) | R34: =IF(IFERROR(VLOOKUP($D34,party!$A:$D,3,0),"")="","",IFERROR(VLOOKUP($D34,party!$A:$D,3,0),"")) -> https://en.wikipedia.org/wiki/Democratic_Party_(United_States) | S34: =IF(IFERROR(VLOOKUP($D34,party!$A:$D,4,0),"")="","",IFERROR(VLOOKUP($D34,party!$A:$D,4,0),"")) -> The Democratic Party is one of the two major contemporary political parties in the United States. Since the late 1850s, its main political rival has been the Republican Party; the two parties have since dominated American politics. The Democratic Party was founded in 1828. The Democratic Party is the world's oldest active political party. It initially supported expansive presidential power, the interests of slave states, agrarianism, and geographical expansionism, while opposing a national bank and high tariffs. It split in 1860 over slavery and won the presidency only twice between 1860 and 1912, although it won the popular vote two more times in that period. | T34: =IF(H34="", "", VALUE(H34)) -> 0.468 | U34: =_xlfn.CONCAT(TEXT(A34,"#"), IF(AND(A34>=10, A34<=19), "th", IF(MOD(A34,10) = 1, "st", IF(MOD(A34,10) = 2, "nd", IF(MOD(A34,10) = 3, "rd", "th"))))) -> 14th | V34: FALSE | W34: Martin Van Buren | X34: =IF(V34, W34, "") | Y34: =IF(NOT(V34), W34, "") -> Martin Van Buren | Z34: =_xlfn.CONCAT("https://en.wikipedia.org/wiki/", C34, "_United_States_presidential_election") -> https://en.wikipedia.org/wiki/1840_United_States_presidential_election
A35: 14 | B35: =VLOOKUP(D35,party!A:E,5,0) -> 15 | C35: 1840 | D35: Whig | E35: William Henry Harrison | G35: 1275390 | H35: 0.529 | I35: 234 | P35: =TEXT(H35,"0.0%") -> 52.9% | Q35: =IF(IFERROR(VLOOKUP($D35,party!$A:$D,2,0),"")="","",IFERROR(VLOOKUP($D35,party!$A:$D,2,0),"")) | R35: =IF(IFERROR(VLOOKUP($D35,party!$A:$D,3,0),"")="","",IFERROR(VLOOKUP($D35,party!$A:$D,3,0),"")) -> https://en.wikipedia.org/wiki/Whig_Party_(United_States) | S35: =IF(IFERROR(VLOOKUP($D35,party!$A:$D,4,0),"")="","",IFERROR(VLOOKUP($D35,party!$A:$D,4,0),"")) -> The Whig Party was a mid-19th century political party in the United States. Alongside the Democratic Party, it was one of two major parties between the late 1830s and the early 1850s and part of the Second Party System. The Whigs emerged in the 1830s in opposition to President Andrew Jackson, pulling together former members of the National Republican Party, the Anti-Masonic Party, and disaffected Democrats. | T35: =IF(H35="", "", VALUE(H35)) -> 0.529 | U35: =_xlfn.CONCAT(TEXT(A35,"#"), IF(AND(A35>=10, A35<=19), "th", IF(MOD(A35,10) = 1, "st", IF(MOD(A35,10) = 2, "nd", IF(MOD(A35,10) = 3, "rd", "th"))))) -> 14th | V35: TRUE | X35: =IF(V35, W35, "") | Y35: =IF(NOT(V35), W35, "") | Z35: =_xlfn.CONCAT("https://en.wikipedia.org/wiki/", C35, "_United_States_presidential_election") -> https://en.wikipedia.org/wiki/1840_United_States_presidential_election
A36: 15 | B36: =VLOOKUP(D36,party!A:E,5,0) -> 26 | C36: 1844 | D36: Democratic | E36: James K. Polk | G36: 1339494 | H36: 0.495 | I36: 170 | P36: =TEXT(H36,"0.0%") -> 49.5% | Q36: =IF(IFERROR(VLOOKUP($D36,party!$A:$D,2,0),"")="","",IFERROR(VLOOKUP($D36,party!$A:$D,2,0),"")) | R36: =IF(IFERROR(VLOOKUP($D36,party!$A:$D,3,0),"")="","",IFERROR(VLOOKUP($D36,party!$A:$D,3,0),"")) -> https://en.wikipedia.org/wiki/Democratic_Party_(United_States) | S36: =IF(IFERROR(VLOOKUP($D36,party!$A:$D,4,0),"")="","",IFERROR(VLOOKUP($D36,party!$A:$D,4,0),"")) -> The Democratic Party is one of the two major contemporary political parties in the United States. Since the late 1850s, its main political rival has been the Republican Party; the two parties have since dominated American politics. The Democratic Party was founded in 1828. The Democratic Party is the world's oldest active political party. It initially supported expansive presidential power, the interests of slave states, agrarianism, and geographical expansionism, while opposing a national bank and high tariffs. It split in 1860 over slavery and won the presidency only twice between 1860 and 1912, although it won the popular vote two more times in that period. | T36: =IF(H36="", "", VALUE(H36)) -> 0.495 | U36: =_xlfn.CONCAT(TEXT(A36,"#"), IF(AND(A36>=10, A36<=19), "th", IF(MOD(A36,10) = 1, "st", IF(MOD(A36,10) = 2, "nd", IF(MOD(A36,10) = 3, "rd", "th"))))) -> 15th | V36: TRUE | X36: =IF(V36, W36, "") | Y36: =IF(NOT(V36), W36, "") | Z36: =_xlfn.CONCAT("https://en.wikipedia.org/wiki/", C36, "_United_States_presidential_election") -> https://en.wikipedia.org/wiki/1844_United_States_presidential_election
A37: 15 | B37: =VLOOKUP(D37,party!A:E,5,0) -> 15 | C37: 1844 | D37: Whig | G37: 1300004 | H37: 0.481 | I37: 105 | P37: =TEXT(H37,"0.0%") -> 48.1% | Q37: =IF(IFERROR(VLOOKUP($D37,party!$A:$D,2,0),"")="","",IFERROR(VLOOKUP($D37,party!$A:$D,2,0),"")) | R37: =IF(IFERROR(VLOOKUP($D37,party!$A:$D,3,0),"")="","",IFERROR(VLOOKUP($D37,party!$A:$D,3,0),"")) -> https://en.wikipedia.org/wiki/Whig_Party_(United_States) | S37: =IF(IFERROR(VLOOKUP($D37,party!$A:$D,4,0),"")="","",IFERROR(VLOOKUP($D37,party!$A:$D,4,0),"")) -> The Whig Party was a mid-19th century political party in the United States. Alongside the Democratic Party, it was one of two major parties between the late 1830s and the early 1850s and part of the Second Party System. The Whigs emerged in the 1830s in opposition to President Andrew Jackson, pulling together former members of the National Republican Party, the Anti-Masonic Party, and disaffected Democrats. | T37: =IF(H37="", "", VALUE(H37)) -> 0.481 | U37: =_xlfn.CONCAT(TEXT(A37,"#"), IF(AND(A37>=10, A37<=19), "th", IF(MOD(A37,10) = 1, "st", IF(MOD(A37,10) = 2, "nd", IF(MOD(A37,10) = 3, "rd", "th"))))) -> 15th | V37: FALSE | W37: Henry Clay | X37: =IF(V37, W37, "") | Y37: =IF(NOT(V37), W37, "") -> Henry Clay | Z37: =_xlfn.CONCAT("https://en.wikipedia.org/wiki/", C37, "_United_States_presidential_election") -> https://en.wikipedia.org/wiki/1844_United_States_presidential_election
